# Import Bug Verification Report

*Date: 2025-08-12*
*Status: VERIFIED - Bug exists in generated files, not source*

## üîç Investigation Results

### File Analysis
```bash
# component_logic_generator.py exists and has 1934 lines
wc -l autocoder_cc/blueprint_language/component_logic_generator.py
# Result: 1934 lines

# Line 1492 is ALREADY CORRECT:
sed -n '1492p' autocoder_cc/blueprint_language/component_logic_generator.py
# Result: from autocoder_cc.components.composed_base import ComposedComponent
```

### ‚úÖ Finding: Line 1492 is NOT the problem!

## üî¥ ACTUAL PROBLEM FOUND

The issue is in **GENERATED FILES**, not the generator itself:

### Generated Files Have Wrong Import
```bash
# Example from generated system:
generated_systems/system_20250807_071304/scaffolds/todo_api_system/components/todo_controller.py:3
# Contains: from observability import ComposedComponent
# Should be: from autocoder_cc.components.composed_base import ComposedComponent
```

### Root Cause Files
The wrong import is being inserted by:
1. `ast_self_healing.py` - Line 223, 305, 310-312, 436
2. `component_logic_generator_with_observability.py` - References wrong import

## üìã Required Fixes

### 1. Fix ast_self_healing.py
**Line 223** - Change:
```python
# FROM:
new_code=f"...from observability import ComposedComponent..."
# TO:
new_code=f"...from autocoder_cc.components.composed_base import ComposedComponent..."
```

**Line 305** - Change:
```python
# FROM:
'ComposedComponent': 'from observability import ComposedComponent',
# TO:
'ComposedComponent': 'from autocoder_cc.components.composed_base import ComposedComponent',
```

**Lines 310-312** - Change all observability imports to proper paths:
```python
'StandaloneMetricsCollector': 'from autocoder_cc.observability import StandaloneMetricsCollector',
'StandaloneTracer': 'from autocoder_cc.observability import StandaloneTracer', 
'get_logger': 'from autocoder_cc.observability import get_logger',
```

### 2. Fix component_logic_generator_with_observability.py
Update all references to check for the correct import path.

### 3. Fix import_auto_fixer.py
**Line 47** - Update regex pattern:
```python
# FROM:
r'from observability import (.+)'
# TO:
r'from autocoder_cc\.observability import (.+)'
```

## üéØ Validation After Fix

Run after fixing:
```bash
# 1. Regenerate a test system
python -m autocoder_cc.cli generate test_blueprint.yaml

# 2. Check generated files don't have wrong import
grep -r "from observability import" generated_systems/[new_system]/
# Should return nothing

# 3. Check they have correct import
grep -r "from autocoder_cc.components.composed_base import" generated_systems/[new_system]/
# Should find imports
```

## üìä Impact Assessment

### Current State
- 100+ systems in generated_systems/ have wrong import
- This causes the 27.8% validation failure rate
- Files can't find observability module

### After Fix
- New generations will have correct import
- Validation should improve significantly
- May need to regenerate existing systems

## üö® CRITICAL INSIGHT

**The "import bug" is not in component_logic_generator.py line 1492!**

The real issue is that:
1. ast_self_healing.py generates wrong imports
2. These get written to generated component files
3. Generated files can't import from "observability" (should be "autocoder_cc.observability")

## ‚úÖ Action Items

1. [ ] Fix ast_self_healing.py (multiple lines)
2. [ ] Fix component_logic_generator_with_observability.py
3. [ ] Fix import_auto_fixer.py
4. [ ] Test generation with fixed imports
5. [ ] Verify validation improves

---
*This completely changes our understanding of the bug. It's not a single line fix but multiple template fixes.*